<mujoco model="ant">
  <compiler angle="degree" coordinate="local" inertiafromgeom="true"/>
  <option integrator="RK4" timestep="0.01"/>
  <custom>
    <numeric data="0.0 0.0 0.55 1.0 0.0 0.0 0.0 0.0 1.0 0.0 -1.0 0.0 -1.0 0.0 1.0" name="init_qpos"/>
  </custom>
  <default>
    <joint armature="1" damping="1" limited="true"/>
    <geom conaffinity="0" condim="3" density="5.0" friction="1.5 0.1 0.1" margin="0.01" rgba="0.8 0.6 0.4 1"/>
  </default>
  <asset>
    <texture name="ceiling" builtin="gradient" height="100" rgb1="1 1 1" rgb2="0 0 0" type="skybox" width="100" mark="random" random="0.05" markrgb="0.5 0.5 0.5"/>
    <texture builtin="flat" height="1278" mark="cross" markrgb="1 1 1" name="texgeom" random="0.01" rgb1="0.8 0.6 0.4" rgb2="0.8 0.6 0.4" type="cube" width="127"/>
    <texture name="texplane" type="2d" builtin="checker" rgb1="0.2 0.2 0.2" rgb2="0.8 0.8 0.8" width="100" height="100" />
    <material name="MatPlane" reflectance="0.1" shininess="0" specular="1" texrepeat="60 60" texture="texplane"/>
    <material name="geom" texture="texgeom" texuniform="true"/>
  </asset>
  <worldbody>
    <light cutoff="90" diffuse="0.7 0.7 0.7" dir="0 0 -1" directional="false" exponent="10" pos="0 0 2" specular=".3 .3 .3"/>
    <geom conaffinity="1" condim="3" material="MatPlane" name="floor" pos="0 0 0" rgba="0.8 0.9 0.8 1" size="20 20 5" type="plane"/>
     <body name="torso" pos="0 0 0.3">
      <camera name="track" mode="trackcom" pos="0 -2 2" xyaxes="1 0 0 0 1 1"/>
      <camera euler="90 -90 0" fovy="120" name="rgb" pos="0.08 0.0 0.08"/>
      <site name="imu" rgba="1 1 0 1" pos="0.0 0.0 0.14" size="0.02" euler="0 180 0"/>
      <site name="front" rgba="1 1 1 1" pos="0.05 0 0.14" size="0.005"/>
      <geom name="base" pos="0 0 0" size="0.08 0.08 0.03" type="box" mass="0.359" rgba="0 0 0 1"/>
      <geom name="raspy_battery" fromto="-0.01 0 0.015 -0.01 0 0.14" size="0.09" type="cylinder" mass="0.612" rgba="0 0 0 1"/>
      <joint armature="0" damping="0" limited="false" margin="0.01" name="root" pos="0 0 0" type="free"/>

      <body name="front_left_leg" pos="0 0 0">
        <body name="aux_1" pos="0.057 0.057 0">
          <joint axis="0 0 1" name="hip_1" pos="0.0 0.0 0.0" range="-40 40" type="hinge"/>
          <geom fromto="0.0 0.0 0.0 0.037 0.037 0.0" name="hip_1_geom" size="0.03" type="capsule" mass="0.019" rgba="0 0 0 1"/>
          <body name="front_left_ankle" pos="0.037 0.037 0">
            <joint axis="-1 1 0" name="ankle_1" pos="0.0 0.0 0.0" range="0 60" type="hinge"/>
            <geom fromto="0.0 0.0 0.0 0.086 0.086 0.0" name="ankle_1_geom" size="0.02" type="capsule" mass="0.077" rgba="0 0 0 1"/>
          </body>
        </body>
      </body>
      <body name="rear_left_leg" pos="0 0 0">
        <body name="aux_2" pos="-0.057 0.057 0">
          <joint axis="0 0 1" name="hip_2" pos="0.0 0.0 0.0" range="-40 40" type="hinge"/>
          <geom fromto="0.0 0.0 0.0 -0.037 0.037 0.0" name="hip_2_geom" size="0.03" type="capsule" mass="0.019" rgba="0 0 0 1"/>
          <body name="rear_left_ankle" pos="-0.037 0.037 0">
            <joint axis="1 1 0" name="ankle_2" pos="0.0 0.0 0.0" range="-60 0" type="hinge"/>
            <geom fromto="0.0 0.0 0.0 -0.086 0.086 0.0" name="ankle_2_geom" size="0.02" type="capsule" mass="0.077" rgba="0 0 0 1"/>
          </body>
        </body>
      </body>
      <body name="rear_right_leg" pos="0 0 0">
        <body name="aux_3" pos="-0.057 -0.057 0">
          <joint axis="0 0 1" name="hip_3" pos="0.0 0.0 0.0" range="-40 40" type="hinge"/>
          <geom fromto="0.0 0.0 0.0 -0.037 -0.037 0.0" name="hip_3_geom" size="0.03" type="capsule" mass="0.019" rgba="0 0 0 1"/>
          <body name="rear_right_ankle" pos="-0.037 -0.037 0">
            <joint axis="-1 1 0" name="ankle_3" pos="0.0 0.0 0.0" range="-60 0" type="hinge"/>
            <geom fromto="0.0 0.0 0.0 -0.086 -0.086 0.0" name="ankle_3_geom" size="0.02" type="capsule" mass="0.077" rgba="0 0 0 1"/>
          </body>
        </body>
      </body>
      <body name="front_right_leg" pos="0 0 0">
        <body name="aux_4" pos="0.057 -0.057 0">
          <joint axis="0 0 1" name="hip_4" pos="0.0 0.0 0.0" range="-40 40" type="hinge"/>
          <geom fromto="0.0 0.0 0.0 0.037 -0.037 0.0" name="hip_4_geom" size="0.03" type="capsule" mass="0.019" rgba="0 0 0 1"/>
          <body name="front_right_ankle" pos="0.037 -0.037 0">
            <joint axis="1 1 0" name="ankle_4" pos="0.0 0.0 0.0" range="0 60" type="hinge"/>
            <geom fromto="0.0 0.0 0.0 0.086 -0.086 0.0" name="ankle_4_geom" size="0.02" type="capsule" mass="0.077" rgba="0 0 0 1"/>
          </body>
        </body>
      </body>
    </body>
  </worldbody>
  <actuator>
    <position joint="hip_1" kp="200" ctrllimited="true" ctrlrange="-0.69 0.69"/>
    <velocity joint="hip_1" kv="8.72"/>
    <position joint="ankle_1" kp="200" ctrllimited="true"  ctrlrange="0.0 1.05"/>
    <velocity joint="ankle_1" kv="7.85"/>
    <position joint="hip_2" kp="200" ctrllimited="true" ctrlrange="-0.69 0.69"/>
    <velocity joint="hip_2" kv="8.72"/>
    <position joint="ankle_2" kp="200" ctrllimited="true" ctrlrange="-1.05 0"/>
    <velocity joint="ankle_2" kv="7.85"/>
    <position joint="hip_3" kp="200" ctrllimited="true" ctrlrange="-0.69 0.69"/>
    <velocity joint="hip_3" kv="8.72"/>
    <position joint="ankle_3" kp="200" ctrllimited="true" ctrlrange="-1.05 0"/>
    <velocity joint="ankle_3" kv="7.85"/>
    <position joint="hip_4" kp="200" ctrllimited="true" ctrlrange="-0.69 0.69"/>
    <velocity joint="hip_4" kv="8.72"/>
    <position joint="ankle_4" kp="200" ctrllimited="true" ctrlrange="0 1.05"/>
    <velocity joint="ankle_4" kv="7.85"/>
  </actuator>
  <sensor>
    <gyro          name="gyro" site="imu" noise="0.01" cutoff="34.9"/>
    <accelerometer name="accel" site="imu" noise="0.01" cutoff="157"/>
    <magnetometer  name="magneto" site="imu"/>
  </sensor>
</mujoco>
